Workbook

Sheet Summary
A1: # | B1: Test sentence | C1: P (MLE) | D1: P (Laplace) | E1: log P (Laplace)
A2: 1 | B2: I love natural language processing. | C2: =PRODUCT(Test_Calc!F2:F7) | D2: =PRODUCT(Test_Calc!G2:G7) | E2: =LN(D2)
A3: 2 | B3: Students learn machine learning. | C3: =PRODUCT(Test_Calc!F8:F12) | D3: =PRODUCT(Test_Calc!G8:G12) | E3: =LN(D3)
A4: 3 | B4: Natural language processing helps students. | C4: =PRODUCT(Test_Calc!F13:F18) | D4: =PRODUCT(Test_Calc!G13:G18) | E4: =LN(D4)
A5: 4 | B5: I enjoy learning machine learning. | C5: =PRODUCT(Test_Calc!F19:F24) | D5: =PRODUCT(Test_Calc!G19:G24) | E5: =LN(D5)
A6: 5 | B6: Students find machine learning useful. | C6: =PRODUCT(Test_Calc!F25:F30) | D6: =PRODUCT(Test_Calc!G25:G30) | E6: =LN(D6)
A8: MLE: P(w2|w1)=C(w1,w2)/C(w1). Laplace: (C(w1,w2)+1)/(C(w1)+V), V from Unigrams!E1. Sentence probability = product of bigram probabilities.

Sheet Unigrams
A1: Word | B1: Count | D1: Vocabulary size V (incl. and 孺) | E1: Total tokens
B2: 25 | D2: =COUNTA(A2:A21) | E2: =SUM(B2:B21)
A3: 孺 | B3: 25
A4: learning | B4: 17 | D4: Note: counts come from the 25-sentence training corpus, lowercased, punctuation stripped, with /孺 added. V = Vocabulary size including and 孺.
A5: language | B5: 13
A6: natural | B6: 13
A7: processing | B7: 13
A8: machine | B8: 12
A9: students | B9: 9
A10: i | B10: 8
A11: is | B11: 8
A12: interesting | B12: 6
A13: useful | B13: 6
A14: find | B14: 4
A15: study | B15: 4
A16: love | B16: 3
... A21: learn | B21: 2

Sheet Bigrams
A1: w1 | B1: w2 | C1: C(w1,w2) | D1: C(w1) | E1: MLE P(w2|w1) | F1: Laplace P(w2|w1)
A2: language | B2: processing | C2: 13 | D2: =SUMPRODUCT((Unigrams!A2:A21=A2)*(Unigrams!B2:B21)) | E2: =C2/D2 | F2: =(C2+1)/(D2+Unigrams!E1)
A3: natural | B3: language | C3: 13 | D3: =SUMPRODUCT((Unigrams!A2:A21=A3)*(Unigrams!B2:B21)) | E3: =C3/D3 | F3: =(C3+1)/(D3+Unigrams!E1)
A4: machine | B4: learning | C4: 12 | D4: =SUMPRODUCT((Unigrams!A2:A21=A4)*(Unigrams!B2:B21)) | E4: =C4/D4 | F4: =(C4+1)/(D4+Unigrams!E1)
B5: i | C5: 8 | D5: =SUMPRODUCT((Unigrams!A2:A21=A5)*(Unigrams!B2:B21)) | E5: =C5/D5 | F5: =(C5+1)/(D5+Unigrams!E1)
B6: students | C6: 7 | D6: =SUMPRODUCT((Unigrams!A2:A21=A6)*(Unigrams!B2:B21)) | E6: =C6/D6 | F6: =(C6+1)/(D6+Unigrams!E1)
A7: interesting | B7: 孺 | C7: 6 | D7: =SUMPRODUCT((Unigrams!A2:A21=A7)*(Unigrams!B2:B21)) | E7: =C7/D7 | F7: =(C7+1)/(D7+Unigrams!E1)
A8: processing | B8: 孺 | C8: 6 | D8: =SUMPRODUCT((Unigrams!A2:A21=A8)*(Unigrams!B2:B21)) | E8: =C8/D8 | F8: =(C8+1)/(D8+Unigrams!E1)
A9: learning | B9: 孺 | C9: 5 | D9: =SUMPRODUCT((Unigrams!A2:A21=A9)*(Unigrams!B2:B21)) | E9: =C9/D9 | F9: =(C9+1)/(D9+Unigrams!E1)
B10: machine | C10: 4 | D10: =SUMPRODUCT((Unigrams!A2:A21=A10)*(Unigrams!B2:B21)) | E10: =C10/D10 | F10: =(C10+1)/(D10+Unigrams!E1)
B11: natural | C11: 4 | D11: =SUMPRODUCT((Unigrams!A2:A21=A11)*(Unigrams!B2:B21)) | E11: =C11/D11 | F11: =(C11+1)/(D11+Unigrams!E1)
A12: is | B12: interesting | C12: 4 | D12: =SUMPRODUCT((Unigrams!A2:A21=A12)*(Unigrams!B2:B21)) | E12: =C12/D12 | F12: =(C12+1)/(D12+Unigrams!E1)
A13: learning | B13: is | C13: 4 | D13: =SUMPRODUCT((Unigrams!A2:A21=A13)*(Unigrams!B2:B21)) | E13: =C13/D13 | F13: =(C13+1)/(D13+Unigrams!E1)
A14: processing | B14: is | C14: 4 | D14: =SUMPRODUCT((Unigrams!A2:A21=A14)*(Unigrams!B2:B21)) | E14: =C14/D14 | F14: =(C14+1)/(D14+Unigrams!E1)
A15: useful | B15: 孺 | C15: 4 | D15: =SUMPRODUCT((Unigrams!A2:A21=A15)*(Unigrams!B2:B21)) | E15: =C15/D15 | F15: =(C15+1)/(D15+Unigrams!E1)
A16: learning | B16: natural | C16: 3 | D16: =SUMPRODUCT((Unigrams!A2:A21=A16)*(Unigrams!B2:B21)) | E16: =C16/D16 | F16: =(C16+1)/(D16+Unigrams!E1)
B17: learning | C17: 2 | D17: =SUMPRODUCT((Unigrams!A2:A21=A17)*(Unigrams!B2:B21)) | E17: =C17/D17 | F17: =(C17+1)/(D17+Unigrams!E1)
A18: a | B18: useful | C18: 2 | D18: =SUMPRODUCT((Unigrams!A2:A21=A18)*(Unigrams!B2:B21)) | E18: =C18/D18 | F18: =(C18+1)/(D18+Unigrams!E1)
A19: enjoy | B19: learning | C19: 2 | D19: =SUMPRODUCT((Unigrams!A2:A21=A19)*(Unigrams!B2:B21)) | E19: =C19/D19 | F19: =(C19+1)/(D19+Unigrams!E1)
A20: field | B20: 孺 | C20: 2 | D20: =SUMPRODUCT((Unigrams!A2:A21=A20)*(Unigrams!B2:B21)) | E20: =C20/D20 | F20: =(C20+1)/(D20+Unigrams!E1)
A21: find | B21: machine | C21: 2 | D21: =SUMPRODUCT((Unigrams!A2:A21=A21)*(Unigrams!B2:B21)) | E21: =C21/D21 | F21: =(C21+1)/(D21+Unigrams!E1)
A22: find | B22: natural | C22: 2 | D22: =SUMPRODUCT((Unigrams!A2:A21=A22)*(Unigrams!B2:B21)) | E22: =C22/D22 | F22: =(C22+1)/(D22+Unigrams!E1)
A23: helps | B23: students | C23: 2 | D23: =SUMPRODUCT((Unigrams!A2:A21=A23)*(Unigrams!B2:B21)) | E23: =C23/D23 | F23: =(C23+1)/(D23+Unigrams!E1)
A24: i | B24: enjoy | C24: 2 | D24: =SUMPRODUCT((Unigrams!A2:A21=A24)*(Unigrams!B2:B21)) | E24: =C24/D24 | F24: =(C24+1)/(D24+Unigrams!E1)
A25: i | B25: find | C25: 2 | D25: =SUMPRODUCT((Unigrams!A2:A21=A25)*(Unigrams!B2:B21)) | E25: =C25/D25 | F25: =(C25+1)/(D25+Unigrams!E1)
A26: i | B26: love | C26: 2 | D26: =SUMPRODUCT((Unigrams!A2:A21=A26)*(Unigrams!B2:B21)) | E26: =C26/D26 | F26: =(C26+1)/(D26+Unigrams!E1)
A27: i | B27: study | C27: 2 | D27: =SUMPRODUCT((Unigrams!A2:A21=A27)*(Unigrams!B2:B21)) | E27: =C27/D27 | F27: =(C27+1)/(D27+Unigrams!E1)
A28: is | B28: a | C28: 2 | D28: =SUMPRODUCT((Unigrams!A2:A21=A28)*(Unigrams!B2:B21)) | E28: =C28/D28 | F28: =(C28+1)/(D28+Unigrams!E1)
A29: is | B29: useful | C29: 2 | D29: =SUMPRODUCT((Unigrams!A2:A21=A29)*(Unigrams!B2:B21)) | E29: =C29/D29 | F29: =(C29+1)/(D29+Unigrams!E1)
A30: learning | B30: machine | C30: 2 | D30: =SUMPRODUCT((Unigrams!A2:A21=A30)*(Unigrams!B2:B21)) | E30: =C30/D30 | F30: =(C30+1)/(D30+Unigrams!E1)
A31: students | B31: find | C31: 2 | D31: =SUMPRODUCT((Unigrams!A2:A21=A31)*(Unigrams!B2:B21)) | E31: =C31/D31 | F31: =(C31+1)/(D31+Unigrams!E1)
A32: students | B32: learn | C32: 2 | D32: =SUMPRODUCT((Unigrams!A2:A21=A32)*(Unigrams!B2:B21)) | E32: =C32/D32 | F32: =(C32+1)/(D32+Unigrams!E1)
A33: students | B33: study | C33: 2 | D33: =SUMPRODUCT((Unigrams!A2:A21=A33)*(Unigrams!B2:B21)) | E33: =C33/D33 | F33: =(C33+1)/(D33+Unigrams!E1)
A34: students | B34: 孺 | C34: 2 | D34: =SUMPRODUCT((Unigrams!A2:A21=A34)*(Unigrams!B2:B21)) | E34: =C34/D34 | F34: =(C34+1)/(D34+Unigrams!E1)
A35: study | B35: machine | C35: 2 | D35: =SUMPRODUCT((Unigrams!A2:A21=A35)*(Unigrams!B2:B21)) | E35: =C35/D35 | F35: =(C35+1)/(D35+Unigrams!E1)
A36: study | B36: natural | C36: 2 | D36: =SUMPRODUCT((Unigrams!A2:A21=A36)*(Unigrams!B2:B21)) | E36: =C36/D36 | F36: =(C36+1)/(D36+Unigrams!E1)
A37: useful | B37: field | C37: 2 | D37: =SUMPRODUCT((Unigrams!A2:A21=A37)*(Unigrams!B2:B21)) | E37: =C37/D37 | F37: =(C37+1)/(D37+Unigrams!E1)
A38: learn | B38: machine | C38: 1 | D38: =SUMPRODUCT((Unigrams!A2:A21=A38)*(Unigrams!B2:B21)) | E38: =C38/D38 | F38: =(C38+1)/(D38+Unigrams!E1)
A39: learn | B39: natural | C39: 1 | D39: =SUMPRODUCT((Unigrams!A2:A21=A39)*(Unigrams!B2:B21)) | E39: =C39/D39 | F39: =(C39+1)/(D39+Unigrams!E1)
A40: learning | B40: helps | C40: 1 | D40: =SUMPRODUCT((Unigrams!A2:A21=A40)*(Unigrams!B2:B21)) | E40: =C40/D40 | F40: =(C40+1)/(D40+Unigrams!E1)
...

Sheet Test_Calc
A1: Sentence # | B1: w1 | C1: w2 | D1: C(w1,w2) | E1: C(w1) | F1: MLE | G1: Laplace
A2: 1 | C2: i | D2: =SUMPRODUCT((Bigrams!A2:A49=B2)*(Bigrams!B2:B49=C2)*(Bigrams!C2:C49)) | E2: =SUMPRODUCT((Unigrams!A2:A21=B2)*(Unigrams!B2:B21)) | F2: =D2/E2 | G2: =(D2+1)/(E2+Unigrams!E1)
A3: 1 | B3: i | C3: love | D3: =SUMPRODUCT((Bigrams!A2:A49=B3)*(Bigrams!B2:B49=C3)*(Bigrams!C2:C49)) | E3: =SUMPRODUCT((Unigrams!A2:A21=B3)*(Unigrams!B2:B21)) | F3: =D3/E3 | G3: =(D3+1)/(E3+Unigrams!E1)
A4: 1 | B4: love | C4: natural | D4: =SUMPRODUCT((Bigrams!A2:A49=B4)*(Bigrams!B2:B49=C4)*(Bigrams!C2:C49)) | E4: =SUMPRODUCT((Unigrams!A2:A21=B4)*(Unigrams!B2:B21)) | F4: =D4/E4 | G4: =(D4+1)/(E4+Unigrams!E1)
A5: 1 | B5: natural | C5: language | D5: =SUMPRODUCT((Bigrams!A2:A49=B5)*(Bigrams!B2:B49=C5)*(Bigrams!C2:C49)) | E5: =SUMPRODUCT((Unigrams!A2:A21=B5)*(Unigrams!B2:B21)) | F5: =D5/E5 | G5: =(D5+1)/(E5+Unigrams!E1)
A6: 1 | B6: language | C6: processing | D6: =SUMPRODUCT((Bigrams!A2:A49=B6)*(Bigrams!B2:B49=C6)*(Bigrams!C2:C49)) | E6: =SUMPRODUCT((Unigrams!A2:A21=B6)*(Unigrams!B2:B21)) | F6: =D6/E6 | G6: =(D6+1)/(E6+Unigrams!E1)
A7: 1 | B7: processing | C7: 孺 | D7: =SUMPRODUCT((Bigrams!A2:A49=B7)*(Bigrams!B2:B49=C7)*(Bigrams!C2:C49)) | E7: =SUMPRODUCT((Unigrams!A2:A21=B7)*(Unigrams!B2:B21)) | F7: =D7/E7 | G7: =(D7+1)/(E7+Unigrams!E1)
A8: 2 | C8: students | D8: =SUMPRODUCT((Bigrams!A2:A49=B8)*(Bigrams!B2:B49=C8)*(Bigrams!C2:C49)) | E8: =SUMPRODUCT((Unigrams!A2:A21=B8)*(Unigrams!B2:B21)) | F8: =D8/E8 | G8: =(D8+1)/(E8+Unigrams!E1)
A9: 2 | B9: students | C9: learn | D9: =SUMPRODUCT((Bigrams!A2:A49=B9)*(Bigrams!B2:B49=C9)*(Bigrams!C2:C49)) | E9: =SUMPRODUCT((Unigrams!A2:A21=B9)*(Unigrams!B2:B21)) | F9: =D9/E9 | G9: =(D9+1)/(E9+Unigrams!E1)
A10: 2 | B10: learn | C10: machine | D10: =SUMPRODUCT((Bigrams!A2:A49=B10)*(Bigrams!B2:B49=C10)*(Bigrams!C2:C49)) | E10: =SUMPRODUCT((Unigrams!A2:A21=B10)*(Unigrams!B2:B21)) | F10: =D10/E10 | G10: =(D10+1)/(E10+Unigrams!E1)
A11: 2 | B11: machine | C11: learning | D11: =SUMPRODUCT((Bigrams!A2:A49=B11)*(Bigrams!B2:B49=C11)*(Bigrams!C2:C49)) | E11: =SUMPRODUCT((Unigrams!A2:A21=B11)*(Unigrams!B2:B21)) | F11: =D11/E11 | G11: =(D11+1)/(E11+Unigrams!E1)
A12: 2 | B12: learning | C12: 孺 | D12: =SUMPRODUCT((Bigrams!A2:A49=B12)*(Bigrams!B2:B49=C12)*(Bigrams!C2:C49)) | E12: =SUMPRODUCT((Unigrams!A2:A21=B12)*(Unigrams!B2:B21)) | F12: =D12/E12 | G12: =(D12+1)/(E12+Unigrams!E1)
A13: 3 | C13: natural | D13: =SUMPRODUCT((Bigrams!A2:A49=B13)*(Bigrams!B2:B49=C13)*(Bigrams!C2:C49)) | E13: =SUMPRODUCT((Unigrams!A2:A21=B13)*(Unigrams!B2:B21)) | F13: =D13/E13 | G13: =(D13+1)/(E13+Unigrams!E1)
A14: 3 | B14: natural | C14: language | D14: =SUMPRODUCT((Bigrams!A2:A49=B14)*(Bigrams!B2:B49=C14)*(Bigrams!C2:C49)) | E14: =SUMPRODUCT((Unigrams!A2:A21=B14)*(Unigrams!B2:B21)) | F14: =D14/E14 | G14: =(D14+1)/(E14+Unigrams!E1)
A15: 3 | B15: language | C15: processing | D15: =SUMPRODUCT((Bigrams!A2:A49=B15)*(Bigrams!B2:B49=C15)*(Bigrams!C2:C49)) | E15: =SUMPRODUCT((Unigrams!A2:A21=B15)*(Unigrams!B2:B21)) | F15: =D15/E15 | G15: =(D15+1)/(E15+Unigrams!E1)
A16: 3 | B16: processing | C16: helps | D16: =SUMPRODUCT((Bigrams!A2:A49=B16)*(Bigrams!B2:B49=C16)*(Bigrams!C2:C49)) | E16: =SUMPRODUCT((Unigrams!A2:A21=B16)*(Unigrams!B2:B21)) | F16: =D16/E16 | G16: =(D16+1)/(E16+Unigrams!E1)
A17: 3 | B17: helps | C17: students | D17: =SUMPRODUCT((Bigrams!A2:A49=B17)*(Bigrams!B2:B49=C17)*(Bigrams!C2:C49)) | E17: =SUMPRODUCT((Unigrams!A2:A21=B17)*(Unigrams!B2:B21)) | F17: =D17/E17 | G17: =(D17+1)/(E17+Unigrams!E1)
A18: 3 | B18: students | C18: 孺 | D18: =SUMPRODUCT((Bigrams!A2:A49=B18)*(Bigrams!B2:B49=C18)*(Bigrams!C2:C49)) | E18: =SUMPRODUCT((Unigrams!A2:A21=B18)*(Unigrams!B2:B21)) | F18: =D18/E18 | G18: =(D18+1)/(E18+Unigrams!E1)
A19: 4 | C19: i | D19: =SUMPRODUCT((Bigrams!A2:A49=B19)*(Bigrams!B2:B49=C19)*(Bigrams!C2:C49)) | E19: =SUMPRODUCT((Unigrams!A2:A21=B19)*(Unigrams!B2:B21)) | F19: =D19/E19 | G19: =(D19+1)/(E19+Unigrams!E1)
A20: 4 | B20: i | C20: enjoy | D20: =SUMPRODUCT((Bigrams!A2:A49=B20)*(Bigrams!B2:B49=C20)*(Bigrams!C2:C49)) | E20: =SUMPRODUCT((Unigrams!A2:A21=B20)*(Unigrams!B2:B21)) | F20: =D20/E20 | G20: =(D20+1)/(E20+Unigrams!E1)
A21: 4 | B21: enjoy | C21: learning | D21: =SUMPRODUCT((Bigrams!A2:A49=B21)*(Bigrams!B2:B49=C21)*(Bigrams!C2:C49)) | E21: =SUMPRODUCT((Unigrams!A2:A21=B21)*(Unigrams!B2:B21)) | F21: =D21/E21 | G21: =(D21+1)/(E21+Unigrams!E1)
A22: 4 | B22: learning | C22: machine | D22: =SUMPRODUCT((Bigrams!A2:A49=B22)*(Bigrams!B2:B49=C22)*(Bigrams!C2:C49)) | E22: =SUMPRODUCT((Unigrams!A2:A21=B22)*(Unigrams!B2:B21)) | F22: =D22/E22 | G22: =(D22+1)/(E22+Unigrams!E1)
A23: 4 | B23: machine | C23: learning | D23: =SUMPRODUCT((Bigrams!A2:A49=B23)*(Bigrams!B2:B49=C23)*(Bigrams!C2:C49)) | E23: =SUMPRODUCT((Unigrams!A2:A21=B23)*(Unigrams!B2:B21)) | F23: =D23/E23 | G23: =(D23+1)/(E23+Unigrams!E1)
A24: 4 | B24: learning | C24: 孺 | D24: =SUMPRODUCT((Bigrams!A2:A49=B24)*(Bigrams!B2:B49=C24)*(Bigrams!C2:C49)) | E24: =SUMPRODUCT((Unigrams!A2:A21=B24)*(Unigrams!B2:B21)) | F24: =D24/E24 | G24: =(D24+1)/(E24+Unigrams!E1)
A25: 5 | C25: students | D25: =SUMPRODUCT((Bigrams!A2:A49=B25)*(Bigrams!B2:B49=C25)*(Bigrams!C2:C49)) | E25: =SUMPRODUCT((Unigrams!A2:A21=B25)*(Unigrams!B2:B21)) | F25: =D25/E25 | G25: =(D25+1)/(E25+Unigrams!E1)
A26: 5 | B26: students | C26: find | D26: =SUMPRODUCT((Bigrams!A2:A49=B26)*(Bigrams!B2:B49=C26)*(Bigrams!C2:C49)) | E26: =SUMPRODUCT((Unigrams!A2:A21=B26)*(Unigrams!B2:B21)) | F26: =D26/E26 | G26: =(D26+1)/(E26+Unigrams!E1)
A27: 5 | B27: find | C27: machine | D27: =SUMPRODUCT((Bigrams!A2:A49=B27)*(Bigrams!B2:B49=C27)*(Bigrams!C2:C49)) | E27: =SUMPRODUCT((Unigrams!A2:A21=B27)*(Unigrams!B2:B21)) | F27: =D27/E27 | G27: =(D27+1)/(E27+Unigrams!E1)
A28: 5 | B28: machine | C28: learning | D28: =SUMPRODUCT((Bigrams!A2:A49=B28)*(Bigrams!B2:B49=C28)*(Bigrams!C2:C49)) | E28: =SUMPRODUCT((Unigrams!A2:A21=B28)*(Unigrams!B2:B21)) | F28: =D28/E28 | G28: =(D28+1)/(E28+Unigrams!E1)
A29: 5 | B29: learning | C29: useful | D29: =SUMPRODUCT((Bigrams!A2:A49=B29)*(Bigrams!B2:B49=C29)*(Bigrams!C2:C49)) | E29: =SUMPRODUCT((Unigrams!A2:A21=B29)*(Unigrams!B2:B21)) | F29: =D29/E29 | G29: =(D29+1)/(E29+Unigrams!E1)
A30: 5 | B30: useful | C30: 孺 | D30: =SUMPRODUCT((Bigrams!A2:A49=B30)*(Bigrams!B2:B49=C30)*(Bigrams!C2:C49)) | E30: =SUMPRODUCT((Unigrams!A2:A21=B30)*(Unigrams!B2:B21)) | F30: =D30/E30 | G30: =(D30+1)/(E30+Unigrams!E1)
